Workbook

Sheet 1. DCF
B2: HOSTESS (TWNK) | O2: Revenue growth | P2: 0.075
B3: In Millions of USD except share Price | O3: EBIT Margin | P3: =AVERAGE( C6 / C5, D6 / D5, E6 / E5, F6 / F5 ) -> 0.17111023
B4: Year | C4: 2020 | D4: 2021 | E4: 2022 | F4: 2023 | G4: 2024 | H4: 2025 | I4: 2026 | J4: 2027 | K4: 2028 | L4: 2029 | M4: 2030 | O4: D&A as % of Revenue | P4: =AVERAGE( C7 / C5, D7 / D5, E7 / E5, F7 / F5 ) -> 0.046793494
B5: Revenue | C5: ='Income statement '!G6 -> 1016.609 | D5: ='Income statement '!H6 -> 1142.036 | E5: ='Income statement '!I6 -> 1358.207 | F5: ='Income statement '!J6 -> 1390.019 | G5: =F5*(1+'2. Assumptions'!$C$3) -> 1494.2704 | H5: =G5*(1+'2. Assumptions'!$C$3) -> 1606.3407 | I5: =H5*(1+'2. Assumptions'!$C$3) -> 1726.8163 | J5: =I5*(1+'2. Assumptions'!$C$3) -> 1856.3275 | K5: =J5*(1+'2. Assumptions'!$C$3) -> 1995.552 | L5: =K5*(1+'2. Assumptions'!$C$3) -> 2145.2184 | M5: =L5*(1+'2. Assumptions'!$C$3) -> 2306.1098 | O5: Tax Rate | P5: =AVERAGE( '[1]Income statement '!G34 / '[1]Income statement '!G33, '[1]Income statement '!H34 / '[1]Income statement '!H33, '[1]Income statement '!I34 / '[1]Income statement '!I33, '[1]Income statement '!J34 / '[1]Income statement '!J33 ) -> 0.22676869
B6: EBIT | C6: ='Income statement '!G65 -> 179.243 | D6: ='Income statement '!H18 -> 211.157 | E6: ='Income statement '!I18 -> 220.278 | F6: ='Income statement '!J18 -> 223.86 | G6: =F6*(1+'2. Assumptions'!$C$4) -> 262.16474 | H6: =G6*(1+'2. Assumptions'!$C$4) -> 307.0238 | I6: =H6*(1+'2. Assumptions'!$C$4) -> 359.55872 | J6: =I6*(1+'2. Assumptions'!$C$4) -> 421.08289 | K6: =J6*(1+'2. Assumptions'!$C$4) -> 493.13448 | L6: =K6*(1+'2. Assumptions'!$C$4) -> 577.51483 | M6: =L6*(1+'2. Assumptions'!$C$4) -> 676.33352 | O6: Capex as % of Revenue | P6: =AVERAGE( C9 / C5, D9 / D5, F9 / F5 ) -> 0.053100465
B7: Depreciation and Amortization | C7: ='Cash Flow '!H8 -> 54.94 | D7: ='Cash Flow '!I8 -> 51.681 | E7: ='Cash Flow '!J8 -> 60.086 | F7: ='Cash Flow '!K8 -> 60.659 | G7: =G5*('2. Assumptions'!$C$5) -> 69.922135 | H7: =H5*('2. Assumptions'!$C$5) -> 75.166295 | I7: =I5*('2. Assumptions'!$C$5) -> 80.803767 | J7: =J5*('2. Assumptions'!$C$5) -> 86.864049 | K7: =K5*('2. Assumptions'!$C$5) -> 93.378853 | L7: =L5*('2. Assumptions'!$C$5) -> 100.38227 | M7: =M5*('2. Assumptions'!$C$5) -> 107.91094 | O7: ΔWC as % of Revenue | P7: =AVERAGE( D15 / D5, E15 / E5, F15 / F5 ) -> 0.017952357
B8: YoY | C8: =C7/C5 -> 0.05404241 | D8: =D7/D5 -> 0.04525339 | E8: =E7/E5 -> 0.044239207 | F8: =F7/F5 -> 0.043638972 | G8: =G7/G5 -> 0.046793494 | O8: Terminal Growth Rate | P8: 0.02
B9: Capex | C9: =-('Cash Flow '!H27 + 'Cash Flow '!H28) -> 58.252 | D9: =-('Cash Flow '!I27 + 'Cash Flow '!I28) -> 65.425 | E9: =-('Cash Flow '!J27 + 'Cash Flow '!J28) -> 130.497 | F9: =-('Cash Flow '!K27 + 'Cash Flow '!K28) -> 62.152 | G9: =G5*('2. Assumptions'!$C$7) -> 79.346454 | H9: =H5*('2. Assumptions'!$C$7) -> 85.297438 | I9: =I5*('2. Assumptions'!$C$7) -> 91.694746 | J9: =J5*('2. Assumptions'!$C$7) -> 98.571852 | K9: =K5*('2. Assumptions'!$C$7) -> 105.96474 | L9: =L5*('2. Assumptions'!$C$7) -> 113.9121 | M9: =M5*('2. Assumptions'!$C$7) -> 122.4555
B10: Current Assets | C10: ='Balance sheet '!H22 -> 369.546 | D10: ='Balance sheet '!I22 -> 460.716 | E10: ='Balance sheet '!J22 -> 367.062 | F10: =F5*(34.5/100) -> 479.55655 | G10: =G5*(34.5/100) -> 515.5233 | H10: =H5*(34.5/100) -> 554.18754 | I10: =I5*(34.5/100) -> 595.75161 | J10: =J5*(34.5/100) -> 640.43298 | K10: =K5*(34.5/100) -> 688.46545 | L10: =L5*(34.5/100) -> 740.10036 | M10: =M5*(34.5/100) -> 795.60789 | N10: =AVERAGE(C10/C5, D10/D5, E10/E5) -> 0.34572656
B11: YoY | C11: =C10/C5 -> 0.36350849 | D11: =D10/D5 -> 0.40341635 | E11: =E10/E5 -> 0.27025483 | F11: =F10/F5 -> 0.345 | G11: =G10/G5 -> 0.345
B12: Current Liabilities | C12: ='Balance sheet '!H51 -> 190.394 | D12: ='Balance sheet '!I51 -> 193.629 | E12: ='Balance sheet '!J51 -> 224.311 | F12: =F5*(17.39/100) -> 241.7243 | G12: =G5*(17.39/100) -> 259.85363 | H12: =H5*(17.39/100) -> 279.34265 | I12: =I5*(17.39/100) -> 300.29335 | J12: =J5*(17.39/100) -> 322.81535 | K12: =K5*(17.39/100) -> 347.0265 | L12: =L5*(17.39/100) -> 373.05349 | M12: =M5*(17.39/100) -> 401.0325 | N12: =AVERAGE(C12/C5, D12/D5, E12/E5) -> 0.1739943
B13: YoY | C13: =C12/C5 -> 0.18728341 | D13: =D12/D5 -> 0.16954719 | E13: =E12/E5 -> 0.16515229 | F13: =F12/F5 -> 0.1739 | G13: =G12/G5 -> 0.1739
B14: Net Working Capital | C14: =C10-C12 -> 179.152 | D14: =D10-D12 -> 267.087 | E14: =E10-E12 -> 142.751 | F14: =F10-F12 -> 237.83225 | G14: =G10-G12 -> 255.66967 | H14: =H10-H12 -> 274.84489 | I14: =I10-I12 -> 295.45826 | J14: =J10-J12 -> 317.61763 | ... M14: =M10-M12 -> 394.57539
B15: Change in Working Capital | D15: =D14-C14 -> 87.935 | E15: =E14-D14 -> -124.336 | F15: =F14-E14 -> 95.081251 | G15: =G14-F14 -> 17.837419 | H15: =H14-G14 -> 19.175225 | I15: =I14-H14 -> 20.613367 | J15: =J14-I14 -> 22.15937 | K15: =K14-J14 -> 23.821322 | ... M15: =M14-L14 -> 27.528516
B16: Unlevered free cash flow | C16: =C6*(1 - 22.68%) + C7 - C9 - C15 -> 135.27869 | D16: =D6*(1 - 22.68%) + D7 - D9 - D15 -> 61.587592 | E16: =E6*(1 - 22.68%) + E7 - E9 - E15 -> 224.24395 | F16: =F6*(1 - 22.68%) + F7 - F9 - F15 -> 76.514301 | G16: =G6*(1 - 22.68%) + G7 - G9 - G15 -> 175.44404 | H16: =H6*(1 - 22.68%) + H7 - H9 - H15 -> 208.08444 | I16: =I6*(1 - 22.68%) + I7 - I9 - I15 -> 246.50645 | J16: =J6*(1 - 22.68%) + J7 - J9 - J15 -> 291.71412 | ... M16: =M6*(1 - 22.68%) + M7 - M9 - M15 -> 480.868
B17: DF | G17: =1/(1+$C$27)^1 -> 0.94190753 | H17: =1/(1+$C$27)^2 -> 0.88718979 | I17: =1/(1+$C$27)^3 -> 0.83565074 | J17: =1/(1+$C$27)^4 -> 0.78710573 | K17: =1/(1+$C$27)^5 -> 0.74138081 | L17: =1/(1+$C$27)^6 -> 0.69831217 | M17: =1/(1+$C$27)^7 -> 0.65774549
B18: PV of FCFF | G18: =G16*G17 -> 165.25206 | H18: =H16*H17 -> 184.61039 | I18: =I16*I17 -> 205.9933 | J18: =J16*J17 -> 229.60985 | K18: =K16*K17 -> 255.69065 | L18: =L16*L17 -> 284.49008 | M18: =M16*M17 -> 316.28876
B19: Terminal Value | G19: =G16*(1+'2. Assumptions'!$C$9)/($C$27-'2. Assumptions'!$C$9) -> 4293.9757 | H19: =H16*(1+'2. Assumptions'!$C$9)/($C$27-'2. Assumptions'!$C$9) -> 5092.8463 | I19: =I16*(1+'2. Assumptions'!$C$9)/($C$27-'2. Assumptions'!$C$9) -> 6033.2214 | J19: =J16*(1+'2. Assumptions'!$C$9)/($C$27-'2. Assumptions'!$C$9) -> 7139.6746 | K19: =K16*(1+'2. Assumptions'!$C$9)/($C$27-'2. Assumptions'!$C$9) -> 8441.0113 | L19: =L16*(1+'2. Assumptions'!$C$9)/($C$27-'2. Assumptions'!$C$9) -> 9970.9949 | M19: =M16*(1+'2. Assumptions'!$C$9)/($C$27-'2. Assumptions'!$C$9) -> 11769.197
B20: Pv of TV | G20: =G19/(1+$C$27)^1 -> 4044.528 | H20: =H19/(1+$C$27)^2 -> 4518.3213 | I20: =I19/(1+$C$27)^3 -> 5041.666 | J20: =J19/(1+$C$27)^4 -> 5619.6788 | K20: =K19/(1+$C$27)^5 -> 6258.0038 | L20: =L19/(1+$C$27)^6 -> 6962.8671 | M20: =M19/(1+$C$27)^7 -> 7741.1365
B21: Enterprise Value | G21: =SUM(G18:M18) + G20 -> 5686.4631
B22: Net Debt | G22: ='3.WACC'!D11 -> 926.77
B23: Equity Value | G23: =G21-G22 -> 4759.6931
B24: Shares outstanding | G24: ='Balance sheet '!J83 -> 133.1172
B25: Implied share price | G25: =G23/G24 -> 35.755658
B27: WACC | C27: ='3.WACC'!C20 -> 0.061675345

Sheet 2. DCF - CONS
B2: HOSTESS (TWNK)
B3: In Millions of USD except share Price
B4: Year | C4: 2020 | D4: 2021 | E4: 2022 | F4: 2023 | G4: 2024 | H4: 2025 | I4: 2026 | J4: 2027 | K4: 2028 | L4: 2029 | M4: 2030
B5: Revenue | C5: ='Income statement '!G6 -> 1016.609 | D5: ='Income statement '!H6 -> 1142.036 | E5: ='Income statement '!I6 -> 1358.207 | F5: ='Income statement '!J6 -> 1390.019 | G5: =F5*(1+'2. Assumptions'!$C$11) -> 1487.3203 | H5: =G5*(1+'2. Assumptions'!$C$11) -> 1591.4328 | I5: =H5*(1+'2. Assumptions'!$C$11) -> 1702.833 | J5: =I5*(1+'2. Assumptions'!$C$11) -> 1822.0314 | K5: =J5*(1+'2. Assumptions'!$C$11) -> 1949.5736 | L5: =K5*(1+'2. Assumptions'!$C$11) -> 2086.0437 | M5: =L5*(1+'2. Assumptions'!$C$11) -> 2232.0668
B6: EBIT | C6: ='Income statement '!G18 -> 179.243 | D6: ='Income statement '!H18 -> 211.157 | E6: ='Income statement '!I18 -> 220.278 | F6: ='Income statement '!J18 -> 223.86 | G6: =F6*(1+'2. Assumptions'!$C$12) -> 255.2004 | H6: =G6*(1+'2. Assumptions'!$C$12) -> 290.92846 | I6: =H6*(1+'2. Assumptions'!$C$12) -> 331.65844 | J6: =I6*(1+'2. Assumptions'!$C$12) -> 378.09062 | K6: =J6*(1+'2. Assumptions'!$C$12) -> 431.02331 | L6: =K6*(1+'2. Assumptions'!$C$12) -> 491.36657 | M6: =L6*(1+'2. Assumptions'!$C$12) -> 560.15789
B7: Depreciation and Amortization | C7: ='Cash Flow '!H8 -> 54.94 | D7: ='Cash Flow '!I8 -> 51.681 | E7: ='Cash Flow '!J8 -> 60.086 | F7: ='Cash Flow '!K8 -> 60.659 | G7: =G5*('2. Assumptions'!$C$13) -> 74.366017 | H7: =H5*('2. Assumptions'!$C$13) -> 79.571638 | I7: =I5*('2. Assumptions'!$C$13) -> 85.141652 | J7: =J5*('2. Assumptions'!$C$13) -> 91.101568 | K7: =K5*('2. Assumptions'!$C$13) -> 97.478678 | L7: =L5*('2. Assumptions'!$C$13) -> 104.30219 | M7: =M5*('2. Assumptions'!$C$13) -> 111.60334
B8: YoY | C8: =C7/C5 -> 0.05404241 | D8: =D7/D5 -> 0.04525339 | E8: =E7/E5 -> 0.044239207 | F8: =F7/F5 -> 0.043638972 | G8: =G7/G5 -> 0.05
B9: Capex | C9: =-('Cash Flow '!H27 + 'Cash Flow '!H28) -> 58.252 | D9: =-('Cash Flow '!I27 + 'Cash Flow '!I28) -> 65.425 | E9: =-('Cash Flow '!J27 + 'Cash Flow '!J28) -> 130.497 | F9: =-('Cash Flow '!K27 + 'Cash Flow '!K28) -> 62.152 | G9: =G5*('2. Assumptions'!$C$15) -> 111.54902 | H9: =H5*('2. Assumptions'!$C$15) -> 119.35746 | I9: =I5*('2. Assumptions'!$C$15) -> 127.71248 | J9: =J5*('2. Assumptions'!$C$15) -> 136.65235 | K9: =K5*('2. Assumptions'!$C$15) -> 146.21802 | L9: =L5*('2. Assumptions'!$C$15) -> 156.45328 | M9: =M5*('2. Assumptions'!$C$15) -> 167.40501
B10: Current Assets | C10: ='Balance sheet '!H22 -> 369.546 | D10: ='Balance sheet '!I22 -> 460.716 | E10: ='Balance sheet '!J22 -> 367.062 | F10: =F5*(34.5/100) -> 479.55655 | G10: =G5*(34.5/100) -> 513.12551 | H10: =H5*(34.5/100) -> 549.0443 | I10: =I5*(34.5/100) -> 587.4774 | J10: =J5*(34.5/100) -> 628.60082 | K10: =K5*(34.5/100) -> 672.60288 | L10: =L5*(34.5/100) -> 719.68508 | M10: =M5*(34.5/100) -> 770.06303 | N10: =AVERAGE(C10/C5, D10/D5, E10/E5) -> 0.34572656
B11: YoY | C11: =C10/C5 -> 0.36350849 | D11: =D10/D5 -> 0.40341635 | E11: =E10/E5 -> 0.27025483 | F11: =F10/F5 -> 0.345 | G11: =G10/G5 -> 0.345
B12: Current Liabilities | C12: ='Balance sheet '!H51 -> 190.394 | D12: ='Balance sheet '!I51 -> 193.629 | E12: ='Balance sheet '!J51 -> 224.311 | F12: =F5*(17.3/100) -> 240.47329 | G12: =G5*(17.3/100) -> 257.30642 | H12: =H5*(17.3/100) -> 275.31787 | I12: =I5*(17.3/100) -> 294.59012 | J12: =J5*(17.3/100) -> 315.21143 | K12: =K5*(17.3/100) -> 337.27622 | L12: =L5*(17.3/100) -> 360.88556 | M12: =M5*(17.3/100) -> 386.14755 | N12: =AVERAGE(C12/C5, D12/D5, E12/E5) -> 0.1739943
B13: YoY | C13: =C12/C5 -> 0.18728341 | D13: =D12/D5 -> 0.16954719 | E13: =E12/E5 -> 0.16515229 | F13: =F12/F5 -> 0.173 | G13: =G12/G5 -> 0.173
B14: Net Working Capital | C14: =C10-C12 -> 179.152 | D14: =D10-D12 -> 267.087 | E14: =E10-E12 -> 142.751 | F14: =F10-F12 -> 239.08327 | G14: =G10-G12 -> 255.8191 | H14: =H10-H12 -> 273.72643 | I14: =I10-I12 -> 292.88728 | J14: =J10-J12 -> 313.38939 | ... M14: =M10-M12 -> 383.91548
B15: Change in Working Capital | D15: =D14-C14 -> 87.935 | E15: =E14-D14 -> -124.336 | F15: =F14-E14 -> 96.332268 | G15: =G14-F14 -> 16.735829 | H15: =H14-G14 -> 17.907337 | I15: =I14-H14 -> 19.16085 | J15: =J14-I14 -> 20.50211 | K15: =K14-J14 -> 21.937258 | ... M15: =M14-L14 -> 25.115966
B16: Unlevered free cash flow | C16: =C6*(1 - 22.68%) + C7 - C9 - C15 -> 135.27869 | D16: =D6*(1 - 22.68%) + D7 - D9 - D15 -> 61.587592 | E16: =E6*(1 - 22.68%) + E7 - E9 - E15 -> 224.24395 | F16: =F6*(1 - 22.68%) + F7 - F9 - F15 -> 75.263284 | G16: =G6*(1 - 22.68%) + G7 - G9 - G15 -> 143.40211 | H16: =H6*(1 - 22.68%) + H7 - H9 - H15 -> 167.25273 | I16: =I6*(1 - 22.68%) + I7 - I9 - I15 -> 194.70663 | J16: =J6*(1 - 22.68%) + J7 - J9 - J15 -> 226.28677 | ... M16: =M6*(1 - 22.68%) + M7 - M9 - M15 -> 352.19645
B17: DF | G17: =1/(1+$C$27)^1 -> 0.93896714 | H17: =1/(1+$C$27)^2 -> 0.88165928 | I17: =1/(1+$C$27)^3 -> 0.82784909 | J17: =1/(1+$C$27)^4 -> 0.77732309 | K17: =1/(1+$C$27)^5 -> 0.72988084 | L17: =1/(1+$C$27)^6 -> 0.68533412 | M17: =1/(1+$C$27)^7 -> 0.64350621
B18: PV of FCFF | G18: =G16*G17 -> 134.64987 | H18: =H16*H17 -> 147.45992 | I18: =I16*I17 -> 161.18771 | J18: =J16*J17 -> 175.89794 | K18: =K16*K17 -> 191.65987 | L18: =L16*L17 -> 208.54763 | M18: =M16*M17 -> 226.6406
B19: Terminal Value | G19: =G16*(1+'2. Assumptions'!$C$17)/($C$27-'2. Assumptions'!$C$17) -> 2911.0629 | H19: =H16*(1+'2. Assumptions'!$C$17)/($C$27-'2. Assumptions'!$C$17) -> 3395.2303 | I19: =I16*(1+'2. Assumptions'!$C$17)/($C$27-'2. Assumptions'!$C$17) -> 3952.5446 | J19: =J16*(1+'2. Assumptions'!$C$17)/($C$27-'2. Assumptions'!$C$17) -> 4593.6215 | K19: =K16*(1+'2. Assumptions'!$C$17)/($C$27-'2. Assumptions'!$C$17) -> 5330.5897 | L19: =L16*(1+'2. Assumptions'!$C$17)/($C$27-'2. Assumptions'!$C$17) -> 6177.3037 | M19: =M16*(1+'2. Assumptions'!$C$17)/($C$27-'2. Assumptions'!$C$17) -> 7149.5879
B20: Pv of TV | G20: =G19/(1+$C$27)^1 -> 2733.3924 | H20: =H19/(1+$C$27)^2 -> 2993.4364 | I20: =I19/(1+$C$27)^3 -> 3272.1104 | J20: =J19/(1+$C$27)^4 -> 3570.7281 | K20: =K19/(1+$C$27)^5 -> 3890.6953 | L20: =L19/(1+$C$27)^6 -> 4233.517 | M20: =M19/(1+$C$27)^7 -> 4600.8042
B21: Enterprise Value | G21: =SUM(G18:M18) + G20 -> 3979.4359
B22: Net Debt | G22: ='3.WACC'!D11 -> 926.77
B23: Equity Value | G23: =G21-G22 -> 3052.6659
B24: Shares outstanding | G24: ='Balance sheet '!J83 -> 133.1172
B25: Implied share price | G25: =G23/G24 -> 22.932167
B27: WACC | C27: 0.065 | D27: Refer to Sheet ASSUMPTIONS

Sheet 3. DCF - OPS
B2: HOSTESS (TWNK)
B3: In Millions of USD except share Price
B4: Year | C4: 2020 | D4: 2021 | E4: 2022 | F4: 2023 | G4: 2024 | H4: 2025 | I4: 2026 | J4: 2027 | K4: 2028 | L4: 2029 | M4: 2030
B5: Revenue | C5: ='Income statement '!G6 -> 1016.609 | D5: ='Income statement '!H6 -> 1142.036 | E5: ='Income statement '!I6 -> 1358.207 | F5: ='Income statement '!J6 -> 1390.019 | G5: =F5*(1+'2. Assumptions'!$C$19) -> 1570.7215 | H5: =G5*(1+'2. Assumptions'!$C$19) -> 1774.9153 | I5: =H5*(1+'2. Assumptions'!$C$19) -> 2005.6542 | J5: =I5*(1+'2. Assumptions'!$C$19) -> 2266.3893 | K5: =J5*(1+'2. Assumptions'!$C$19) -> 2561.0199 | L5: =K5*(1+'2. Assumptions'!$C$19) -> 2893.9525 | M5: =L5*(1+'2. Assumptions'!$C$19) -> 3270.1663
B6: EBIT | C6: ='Income statement '!G18 -> 179.243 | D6: ='Income statement '!H18 -> 211.157 | E6: ='Income statement '!I18 -> 220.278 | F6: ='Income statement '!J18 -> 223.86 | G6: =F6*(1+'2. Assumptions'!$C$20) -> 268.632 | H6: =G6*(1+'2. Assumptions'!$C$20) -> 322.3584 | I6: =H6*(1+'2. Assumptions'!$C$20) -> 386.83008 | J6: =I6*(1+'2. Assumptions'!$C$20) -> 464.1961 | K6: =J6*(1+'2. Assumptions'!$C$20) -> 557.03532 | L6: =K6*(1+'2. Assumptions'!$C$20) -> 668.44238 | M6: =L6*(1+'2. Assumptions'!$C$20) -> 802.13085
B7: Depreciation and Amortization | C7: ='Cash Flow '!H8 -> 54.94 | D7: ='Cash Flow '!I8 -> 51.681 | E7: ='Cash Flow '!J8 -> 60.086 | F7: ='Cash Flow '!K8 -> 60.659 | G7: =G5*('2. Assumptions'!$C$21) -> 62.828859 | H7: =H5*('2. Assumptions'!$C$21) -> 70.99661 | I7: =I5*('2. Assumptions'!$C$21) -> 80.22617 | J7: =J5*('2. Assumptions'!$C$21) -> 90.655572 | K7: =K5*('2. Assumptions'!$C$21) -> 102.4408 | L7: =L5*('2. Assumptions'!$C$21) -> 115.7581 | M7: =M5*('2. Assumptions'!$C$21) -> 130.80665
B8: YoY | C8: =C7/C5 -> 0.05404241 | D8: =D7/D5 -> 0.04525339 | E8: =E7/E5 -> 0.044239207 | F8: =F7/F5 -> 0.043638972 | G8: =G7/G5 -> 0.04
B9: Capex | C9: =-('Cash Flow '!H27 + 'Cash Flow '!H28) -> 58.252 | D9: =-('Cash Flow '!I27 + 'Cash Flow '!I28) -> 65.425 | E9: =-('Cash Flow '!J27 + 'Cash Flow '!J28) -> 130.497 | F9: =-('Cash Flow '!K27 + 'Cash Flow '!K28) -> 62.152 | G9: =G5*('2. Assumptions'!$C$23) -> 78.536074 | H9: =H5*('2. Assumptions'!$C$23) -> 88.745763 | I9: =I5*('2. Assumptions'!$C$23) -> 100.28271 | J9: =J5*('2. Assumptions'!$C$23) -> 113.31946 | K9: =K5*('2. Assumptions'!$C$23) -> 128.051 | L9: =L5*('2. Assumptions'!$C$23) -> 144.69762 | M9: =M5*('2. Assumptions'!$C$23) -> 163.50832
B10: Current Assets | C10: ='Balance sheet '!H22 -> 369.546 | D10: ='Balance sheet '!I22 -> 460.716 | E10: ='Balance sheet '!J22 -> 367.062 | F10: =F5*(34.5/100) -> 479.55655 | G10: =G5*(34.5/100) -> 541.89891 | H10: =H5*(34.5/100) -> 612.34577 | I10: =I5*(34.5/100) -> 691.95071 | J10: =J5*(34.5/100) -> 781.90431 | K10: =K5*(34.5/100) -> 883.55187 | L10: =L5*(34.5/100) -> 998.41361 | M10: =M5*(34.5/100) -> 1128.2074 | N10: =AVERAGE(C10/C5, D10/D5, E10/E5) -> 0.34572656
B11: YoY | C11: =C10/C5 -> 0.36350849 | D11: =D10/D5 -> 0.40341635 | E11: =E10/E5 -> 0.27025483 | F11: =F10/F5 -> 0.345 | G11: =G10/G5 -> 0.345
B12: Current Liabilities | C12: ='Balance sheet '!H51 -> 190.394 | D12: ='Balance sheet '!I51 -> 193.629 | E12: ='Balance sheet '!J51 -> 224.311 | F12: =F5*(17.3/100) -> 240.47329 | G12: =G5*(17.3/100) -> 271.73481 | H12: =H5*(17.3/100) -> 307.06034 | I12: =I5*(17.3/100) -> 346.97818 | J12: =J5*(17.3/100) -> 392.08535 | K12: =K5*(17.3/100) -> 443.05644 | L12: =L5*(17.3/100) -> 500.65378 | M12: =M5*(17.3/100) -> 565.73877 | N12: =AVERAGE(C12/C5, D12/D5, E12/E5) -> 0.1739943
B13: YoY | C13: =C12/C5 -> 0.18728341 | D13: =D12/D5 -> 0.16954719 | E13: =E12/E5 -> 0.16515229 | F13: =F12/F5 -> 0.173 | G13: =G12/G5 -> 0.173
B14: Net Working Capital | C14: =C10-C12 -> 179.152 | D14: =D10-D12 -> 267.087 | E14: =E10-E12 -> 142.751 | F14: =F10-F12 -> 239.08327 | G14: =G10-G12 -> 270.16409 | H14: =H10-H12 -> 305.28542 | I14: =I10-I12 -> 344.97253 | J14: =J10-J12 -> 389.81896 | ... M14: =M10-M12 -> 562.46861
B15: Change in Working Capital | D15: =D14-C14 -> 87.935 | E15: =E14-D14 -> -124.336 | F15: =F14-E14 -> 96.332268 | G15: =G14-F14 -> 31.080825 | H15: =H14-G14 -> 35.121332 | I15: =I14-H14 -> 39.687105 | J15: =J14-I14 -> 44.846429 | K15: =K14-J14 -> 50.676465 | ... M15: =M14-L14 -> 64.708778
B16: Unlevered free cash flow | C16: =C6*(1 - 22.68%) + C7 - C9 - C15 -> 135.27869 | D16: =D6*(1 - 22.68%) + D7 - D9 - D15 -> 61.587592 | E16: =E6*(1 - 22.68%) + E7 - E9 - E15 -> 224.24395 | F16: =F6*(1 - 22.68%) + F7 - F9 - F15 -> 75.263284 | G16: =G6*(1 - 22.68%) + G7 - G9 - G15 -> 160.91822 | H16: =H6*(1 - 22.68%) + H7 - H9 - H15 -> 196.37703 | I16: =I6*(1 - 22.68%) + I7 - I9 - I15 -> 239.35337 | J16: =J6*(1 - 22.68%) + J7 - J9 - J15 -> 291.4061 | ... M16: =M6*(1 - 22.68%) + M7 - M9 - M15 -> 522.79714
B17: DF | H17: =1/(1+$C$27)^1 -> 0.95238095 | I17: =1/(1+$C$27)^2 -> 0.90702948 | J17: =1/(1+$C$27)^3 -> 0.8638376 | K17: =1/(1+$C$27)^4 -> 0.82270247 | L17: =1/(1+$C$27)^5 -> 0.78352617 | M17: =1/(1+$C$27)^6 -> 0.7462154
B18: PV of FCFF | H18: =H16*H17 -> 187.02574 | I18: =I16*I17 -> 217.10056 | J18: =J16*J17 -> 251.72755 | K18: =K16*K17 -> 291.57649 | L18: =L16*L17 -> 337.41435 | M18: =M16*M17 -> 390.11927
B19: Terminal Value | H19: =H16*(1+'2. Assumptions'!$C$25)/($C$27-'2. Assumptions'!$C$25) -> 8051.4582 | I19: =I16*(1+'2. Assumptions'!$C$25)/($C$27-'2. Assumptions'!$C$25) -> 9813.4882 | J19: =J16*(1+'2. Assumptions'!$C$25)/($C$27-'2. Assumptions'!$C$25) -> 11947.65 | K19: =K16*(1+'2. Assumptions'!$C$25)/($C$27-'2. Assumptions'!$C$25) -> 14530.935 | L19: =L16*(1+'2. Assumptions'!$C$25)/($C$27-'2. Assumptions'!$C$25) -> 17656.064 | M19: =M16*(1+'2. Assumptions'!$C$25)/($C$27-'2. Assumptions'!$C$25) -> 21434.683
B20: Pv of TV | H20: =H19/(1+$C$27)^1 -> 7668.0555 | I20: =I19/(1+$C$27)^2 -> 8901.1231 | J20: =J19/(1+$C$27)^3 -> 10320.829 | K20: =K19/(1+$C$27)^4 -> 11954.636 | L20: =L19/(1+$C$27)^5 -> 13833.988 | M20: =M19/(1+$C$27)^6 -> 15994.89
B21: Enterprise Value | H21: =SUM(H18:M18) + H20 -> 9343.0194
B22: Net Debt | H22: ='3.WACC'!D11 -> 926.77
B23: Equity Value | H23: =H21-H22 -> 8416.2494
B24: Shares outstanding | H24: ='Balance sheet '!J83 -> 133.1172
B25: Implied share price | H25: =H23/H24 -> 63.224357
B27: WACC | C27: 0.05 | D27: Refer to Sheet ASSUMPTIONS

Sheet 2. Assumptions
B2: Key Valuation
B3: Revenue growth | C3: ='1. DCF'!P2 -> 0.075
B4: EBIT Margin | C4: ='1. DCF'!P3 -> 0.17111023
B5: D&A as % of Revenue | C5: ='1. DCF'!P4 -> 0.046793494
B6: Tax Rate | C6: ='1. DCF'!P5 -> 0.22676869
B7: Capex as % of Revenue | C7: ='1. DCF'!P6 -> 0.053100465
B8: ΔWC as % of Revenue | C8: ='1. DCF'!P7 -> 0.017952357
B9: Terminal Growth Rate | C9: ='1. DCF'!P8 -> 0.02
B10: Conservative
B11: Revenue growth | C11: 0.07
B12: EBIT Margin | C12: 0.14
B13: D&A as % of Revenue | C13: 0.05
B14: Tax Rate | C14: 0.2268 | H14: 0
B15: Capex as % of Revenue | C15: 0.075
B16: ΔWC as % of Revenue | C16: 0.02
B17: Terminal Growth Rate | C17: 0.015
B18: Optimistic
B19: Revenue growth | C19: 0.13
B20: EBIT Margin | C20: 0.2
B21: D&A as % of Revenue | C21: 0.04
B22: Tax Rate | C22: 0.2268
B23: Capex as % of Revenue | C23: 0.05
B24: ΔWC as % of Revenue | C24: 0.01
B25: Terminal Growth Rate | C25: 0.025

Sheet 3.WACC
B2: Cost of Equity
B3: Rf | D3: 0.042
B4: Beta (Adjusted) | D4: 0.591
B5: Equity risk premium | D5: 0.0428
B6: COE | D6: =D3+(D4*D5) -> 0.0672948
B8: Cost of Debt
B9: Interest Expense | D9: ='Income statement '!I20 -> 40.95
B10: Total Debt | D10: ='Balance sheet '!J41 + 'Balance sheet '!J52 -> 1025.354
B11: Net Debt | D11: =D10 - '[2]Balance sheet '!J8 -> 926.77
B12: Cost of debt | D12: =D9/D11 -> 0.04418572
B14: Net Debt
B15: Market Cap (E) | D15: ='Equity Valuation- Peers data '!B2 -> 4449.47
B16: Enterprise value | D16: ='Equity Valuation- Peers data '!C2 -> 5358.33
B17: Net Debt (D) | D17: =D16-D15 -> 908.86
B19: Tax rate | C19: 0.2268
B20: WACC | C20: =(D15/(D17+D15))*D6+(D17/(D17+D15))*D12*(1-C19) -> 0.061675345

Sheet 4. Sensitivity Analysis
B2: Scenario | C2: Revenue Growth | D2: EBIT Margin | E2: WACC | F2: Terminal Growth | G2: Implied Share Price | H2: Comments
B3: Conservative | C3: 0.07 | D3: 0.14 | E3: 0.065 | F3: 0.015 | G3: ='2. DCF - CONS'!G25 -> 22.932167
B4: Base Case | C4: ='2. Assumptions'!C3 -> 0.075 | D4: ='2. Assumptions'!C4 -> 0.17111023 | E4: ='1. DCF'!C27 -> 0.061675345 | F4: ='2. Assumptions'!C9 -> 0.02 | G4: ='1. DCF'!G25 -> 35.755658
B5: Optimistic | C5: 0.13 | D5: 0.2 | E5: 0.05 | F5: 0.025 | G5: 63.22

Sheet Income statement 
A2: Hostess Brands Inc (TWNK US) - BBG Adjusted
A4: In Millions of USD except Per Share | C4: FY 2016 | D4: FY 2017 | E4: FY 2018 | F4: FY 2019 | G4: FY 2020 | H4: FY 2021 | I4: FY 2022 | J4: Last 12M | K4: FY 2023 Est | L4: FY 2024 Est
A5: 12 Months Ending | C5: 12/31/2016 | D5: 12/31/2017 | E5: 12/31/2018 | F5: 12/31/2019 | G5: 12/31/2020 | H5: 12/31/2021 | I5: 12/31/2022 | J5: 09/30/2023 | K5: 12/31/2023 | L5: 12/31/2024
A6: Revenue | B6: SALES_REV_TURN | C6: 727.586 | D6: 776.188 | E6: 850.389 | F6: 907.675 | G6: 1016.609 | H6: 1142.036 | I6: 1358.207 | J6: 1390.019 | K6: 1426 | L6: 1483
A7: + Sales & Services Revenue | B7: IS_SALES_AND_SERVICES_REVENUES | C7: 727.586 | D7: 776.188 | E7: 850.389 | F7: 907.675 | G7: 1016.609 | H7: 1142.036 | I7: 1358.207 | J7: 705.158
A8: - Cost of Revenue | B8: IS_COGS_TO_FE_AND_PP_AND_G | C8: 422.343 | D8: 449.29 | E8: 583.112 | F8: 598.46 | G8: 649.326 | H8: 732.053 | I8: 892.528 | J8: 901.594
A9: + Cost of Goods & Services | B9: IS_COG_AND_SERVICES_SOLD | C9: 422.343 | D9: 449.29 | E9: 583.112 | F9: 598.46 | G9: 649.326 | H9: 732.053 | I9: 892.528 | J9: 459.384
A10: Gross Profit | B10: GROSS_PROFIT | C10: 305.243 | D10: 326.898 | E10: 267.277 | F10: 309.215 | G10: 367.283 | H10: 409.983 | I10: 465.679 | J10: 488.425
A11: + Other Operating Income | B11: IS_OTHER_OPER_INC | C11: 0 | D11: 50.222 | E11: 0 | F11: 0 | G11: 0 | H11: 0 | I11: 0 | J11: 0
A12: - Operating Expenses | B12: IS_OPERATING_EXPN | C12: 116.475 | D12: 141.797 | E12: 129.394 | F12: 158.793 | G12: 188.04 | H12: 198.826 | I12: 245.401 | J12: 264.565
A13: + Selling, General & Admin | B13: IS_SGA_EXPENSE | C13: 112.347 | D13: 118.033 | E13: 117.9 | F13: 127.837 | G13: 179.603 | H13: 187.144 | I13: 222.749 | J13: 118.038
A14: + Selling & Marketing | B14: IS_SELLING_EXPENSES | C14: 66.634 | D14: 65.09 | E14: 65.14 | F14: 70.494 | G14: 92.453 | H14: 87.971 | I14: 103.296 | J14: 62.921
A15: + General & Administrative | B15: IS_GENERAL_AND_ADMINISTRATIVE | C15: 45.713 | D15: 52.943 | E15: 52.76 | F15: 57.343 | G15: 87.15 | H15: 99.173 | I15: 119.453 | J15: 55.117
A16: + Research & Development | B16: IS_OPERATING_EXPENSES_RD | C16: 0 | D16: 0 | E16: 0 | F16: 0 | G16: 0 | H16: 0 | I16: 0
A17: + Other Operating Expense | B17: IS_OTHER_OPERATING_EXPENSES | C17: 4.128 | D17: 23.764 | E17: 11.494 | F17: 30.956 | G17: 8.437 | H17: 11.682 | I17: 22.652 | J17: 22.54
A18: Operating Income (Loss) | B18: IS_OPER_INC | C18: 188.768 | D18: 235.323 | E18: 137.883 | F18: 150.422 | G18: 179.243 | H18: 211.157 | I18: 220.278 | J18: 223.86
A19: - Non-Operating (Income) Loss | B19: IS_NONOP_INCOME_LOSS | C19: 69.411 | D19: 40.534 | E19: -39.606 | F19: 91.84 | G19: 6.608 | H19: 40.926 | I19: 8.994 | J19: 20.947
A20: + Interest Expense, Net | B20: IS_NET_INTEREST_EXPENSE | C20: 67.033 | D20: 39.174 | E20: 39.404 | F20: 39.87 | G20: 42.826 | H20: 39.762 | I20: 40.95 | J20: 20.717
A21: - Interest Income | B21: IS_INT_INC | C21: — | D21: — | E21: — | F21: — | G21: — | H21: — | I21: —
A22: + Foreign Exch (Gain) Loss | B22: IS_FOREIGN_EXCH_LOSS | C22: 0 | D22: 0 | E22: 0 | F22: -7.128 | G22: 0 | H22: 0 | I22: 0
A23: + Other Non-Op (Income) Loss | B23: IS_OTHER_NON_OPERATING_INC_LOSS | C23: 2.378 | D23: 1.36 | E23: -79.01 | F23: 59.098 | G23: -36.218 | H23: 1.164 | I23: -31.956 | J23: 0.23
A24: Pretax Income (Loss), Adjusted | B24: PRETAX_INC | C24: 119.357 | D24: 194.789 | E24: 177.489 | F24: 58.582 | G24: 172.635 | H24: 170.231 | I24: 211.284 | J24: 181.244
A25: - Abnormal Losses (Gains) | B25: IS_ABNORMAL_ITEM | C25: 74.74 | D25: 3.885 | E25: 3.953 | F25: 22.941 | G25: 43.933 | H25: 10.419 | I25: 0 | J25: 7.4720001
A26: + Merger/Acquisition Expense | B26: IS_MERGER_ACQUISITION_EXPENSE | C26: 31.832 | D26: — | E26: 0.297 | F26: 1.914 | G26: 4.282 | H26: 2.8 | I26: —
A27: + Disposal of Assets | B27: IS_GAIN_LOSS_DISPOSAL_ASSETS | C27: — | D27: -0.144 | E27: — | F27: — | G27: — | H27: — | I27: —
A28: + Early Extinguishment of Debt | B28: IS_G_L_ON_EXT_DBT_OR_SETTLE_DBT | C28: -0.763 | D28: 2.554 | E28: — | F28: 1.487 | G28: — | H28: — | I28: —
A29: + Asset Write-Down | B29: IS_IMPAIRMENT_ASSETS | C29: 7.3 | D29: 1.475 | E29: 4.97 | F29: 1.976 | G29: 3.009 | H29: — | I29: —
A30: + Legal Settlement | B30: IS_LEGAL_LITIGATION_SETTLEMENT | C30: 0.751 | D30: — | E30: — | F30: — | G30: — | H30: — | I30: —
A31: + Restructuring | B31: IS_RESTRUCTURING_EXPENSES | C31: 26.747 | D31: — | E31: — | F31: 12.08 | G31: 5.71 | H31: — | I31: —
A32: + Other Abnormal Items | B32: IS_OTHER_ONE_TIME_ITEMS | C32: 8.873 | D32: — | E32: -1.314 | F32: 5.484 | G32: 30.932 | H32: 7.619 | I32: —
A33: Pretax Income (Loss), GAAP | B33: PRETAX_INC | C33: 44.617 | D33: 190.904 | E33: 173.536 | F33: 35.641 | G33: 128.702 | H33: 159.812 | I33: 211.284 | J33: 173.772
A34: - Income Tax Expense (Benefit) | B34: IS_INC_TAX_EXP | C34: -7.323 | D34: -67.204 | E34: 12.954 | F34: 16.892 | G34: 20.405 | H34: 40.513 | I34: 47.089 | J34: 47.293
A35: Income (Loss) from Cont Ops | B35: IS_INC_BEF_XO_ITEM | C35: 51.94 | D35: 258.108 | E35: 160.582 | F35: 18.749 | G35: 108.297 | H35: 119.299 | I35: 164.195 | J35: 126.479
A36: - Net Extraordinary Losses (Gains) | B36: XO_GL_NET_OF_TAX | C36: 0 | D36: 0 | E36: 0 | F36: 0 | G36: 0 | H36: 0 | I36: 0 | J36: 0
A37: + Discontinued Operations | B37: IS_DISCONTINUED_OPERATIONS | C37: 0 | D37: 0 | E37: 0 | F37: 0 | G37: 0 | H37: 0 | I37: 0 | J37: 0
A38: + XO & Accounting Changes | B38: EXTRAORD_ITEMS_ACCOUNTING_CHANGS | C38: 0 | D38: 0 | E38: 0 | F38: 0 | G38: 0 | H38: 0 | I38: 0 | J38: 0
A39: Income (Loss) Incl. MI | B39: NI_INCLUDING_MINORITY_INT_RATIO | C39: 51.94 | D39: 258.108 | E39: 160.582 | F39: 18.749 | G39: 108.297 | H39: 119.299 | I39: 164.195 | J39: 55.298
A40: - Minority Interest | B40: MIN_NONCONTROL_INTEREST_CREDITS | C40: -0.867 | D40: 34.211 | E40: 18.531 | F40: 14.45 | G40: 3.621 | H40: 0 | I40: 0 | J40: 0
A41: Net Income, GAAP | B41: NET_INCOME | C41: 52.807 | D41: 223.897 | E41: 142.051 | F41: 4.299 | G41: 104.676 | H41: 119.299 | I41: 164.195 | J41: 126.479
A42: - Preferred Dividends | B42: IS_TOT_CASH_PFD_DVD | C42: 0 | D42: 0 | E42: 0 | F42: 0 | G42: 0 | H42: 0 | I42: 0 | J42: 0
...

Sheet Balance sheet 
A2: Hostess Brands Inc (TWNK US) - Standardized
A4: In Millions of USD except Per Share | C4: FY 2015 | D4: FY 2016 | E4: FY 2017 | F4: FY 2018 | G4: FY 2019 | H4: FY 2020 | I4: FY 2021 | J4: FY 2022
A5: 12 Months Ending | C5: 12/31/2015 | D5: 12/31/2016 | E5: 12/31/2017 | F5: 12/31/2018 | G5: 12/31/2019 | H5: 12/31/2020 | I5: 12/31/2021 | J5: 12/31/2022
A6: Total Assets
A7: + Cash, Cash Equivalents & STI | B7: CASH_CASH_EQTY_STI_DETAILED | C7: 0.7906 | D7: 26.855 | E7: 135.701 | F7: 146.377 | G7: 285.087 | H7: 173.034 | I7: 249.159 | J7: 116.498
A8: + Cash & Cash Equivalents | B8: BS_CASH_NEAR_CASH_ITEM | C8: 0.7906 | D8: 26.855 | E8: 135.701 | F8: 146.377 | G8: 285.087 | H8: 173.034 | I8: 249.159 | J8: 98.584
A9: + ST Investments | B9: BS_MKT_SEC_OTHER_ST_INVEST | C9: 0 | D9: 0 | E9: 0 | F9: 0 | G9: 0 | H9: 0 | I9: 0 | J9: 17.914
A10: + Accounts & Notes Receiv | B10: BS_ACCT_NOTE_RCV | C10: 0 | D10: 89.237 | E10: 101.012 | F10: 105.679 | G10: 104.892 | H10: 125.55 | I10: 148.18 | J10: 168.783
A11: + Accounts Receivable, Net | B11: BS_ACCTS_REC_EXCL_NOTES_REC | C11: 0 | D11: 89.237 | E11: 101.012 | F11: 105.679 | G11: 104.892 | H11: 125.55 | I11: 148.18 | J11: 168.783
A12: + Notes Receivable, Net | B12: NOTES_RECEIVABLE | C12: 0 | D12: 0 | E12: 0 | F12: 0 | G12: 0 | H12: 0 | I12: 0 | J12: 0
A13: + Inventories | B13: BS_INVENTORIES | C13: 0 | D13: 30.444 | E13: 34.345 | F13: 38.58 | G13: 47.608 | H13: 49.348 | I13: 52.813 | J13: 65.406
A14: + Raw Materials | B14: INVTRY_RAW_MATERIALS | C14: 0 | D14: 0 | E14: 0 | F14: 0 | G14: 21.439 | H14: 22.965 | I14: 22.607 | J14: 35.41
A15: + Work In Process | B15: INVTRY_IN_PROGRESS | C15: 0 | D15: 0 | E15: 0 | F15: 0 | G15: 0 | H15: 0 | I15: 0 | J15: 0
A16: + Finished Goods | B16: INVTRY_FINISHED_GOODS | C16: 0 | D16: 14.229 | E16: 15.471 | F16: 16.446 | G16: 22.513 | H16: 23.583 | I16: 26.988 | J16: 26.133
A17: + Other Inventory | B17: BS_OTHER_INV | C17: 0 | D17: 16.215 | E17: 18.874 | F17: 22.134 | G17: 3.656 | H17: 2.8 | I17: 3.218 | J17: 3.863
A18: + Other ST Assets | B18: OTHER_CURRENT_ASSETS_DETAILED | C18: 0.2591 | D18: 4.827 | E18: 7.97 | F18: 8.806 | G18: 15.569 | H18: 21.614 | I18: 10.564 | J18: 16.375
A19: + Prepaid Expenses | B19: BS_PREPAY | C19: 0.2591 | D19: — | E19: — | F19: — | G19: — | H19: — | I19: — | J19: —
A20: + Derivative & Hedging Assets | B20: BS_DERIV_HEDGING_ASST_ST | C20: 0 | D20: 0 | E20: 0 | F20: 0 | G20: 0 | H20: 0 | I20: 0 | J20: 0
A21: + Misc ST Assets | B21: BS_OTHER_CUR_ASSET_LESS_PREPAY | C21: 0 | D21: 4.827 | E21: 7.97 | F21: 8.806 | G21: 15.569 | H21: 21.614 | I21: 10.564 | J21: 16.375
A22: Total Current Assets | B22: BS_CUR_ASSET_REPORT | C22: 1.0498 | D22: 151.363 | E22: 279.028 | F22: 299.442 | G22: 453.156 | H22: 369.546 | I22: 460.716 | J22: 367.062
A23: + Property, Plant & Equip, Net | B23: BS_NET_FIX_ASSET | C23: 0 | D23: 153.224 | E23: 174.121 | F23: 220.349 | G23: 242.384 | H23: 303.959 | I23: 335.305 | J23: 425.313
A24: + Property, Plant & Equip | B24: BS_GROSS_FIX_ASSET | C24: — | D24: 154.83 | E24: 187.572 | F24: 248.307 | G24: 292.714 | H24: 371.99 | I24: 427.982 | J24: 547.403
A25: - Accumulated Depreciation | B25: BS_ACCUM_DEPR | C25: — | D25: 1.606 | E25: 13.451 | F25: 27.958 | G25: 50.33 | H25: 68.031 | I25: 92.677 | J25: 122.09
A26: + LT Investments & Receivables | B26: BS_LT_INVEST | C26: 0 | D26: 0 | E26: 0 | F26: 0 | G26: 0 | H26: 0 | I26: 0 | J26: 0
A27: + Other LT Assets | B27: BS_OTHER_ASSETS_DEF_CHRG_OTHER | C27: 375.0105 | D27: 2543.305 | E27: 2513.126 | F27: 2490.922 | G27: 2402.161 | H27: 2691.964 | I27: 2670.29 | J27: 2699.824
A28: + Total Intangible Assets | B28: BS_DISCLOSED_INTANGIBLES | C28: 0 | D28: 2535.403 | E28: 2502.534 | F28: 2476.86 | G28: 2389.168 | H28: 2674.518 | I28: 2651.007 | J28: 2627.495
A29: + Goodwill | B29: BS_GOODWILL | C29: 0 | D29: 588.46 | E29: 579.446 | F29: 575.645 | G29: 535.853 | H29: 706.615 | I29: 706.615 | J29: 706.615
A30: + Other Intangible Assets | B30: OTHER_INTANGIBLE_ASSETS_DETAILED | C30: 0 | D30: 1946.943 | E30: 1923.088 | F30: 1901.215 | G30: 1853.315 | H30: 1967.903 | I30: 1944.392 | J30: 1920.88
A31: + Derivative & Hedging Assets | B31: BS_DERIV_HEDGING_ASST_LT | C31: 0 | D31: 0 | E31: 0 | F31: 0 | G31: 0 | H31: 0 | I31: 0 | J31: 0
A32: + Misc LT Assets | B32: OTHER_NONCURRENT_ASSETS_DETAILED | C32: 375.0105 | D32: 7.902 | E32: 10.592 | F32: 14.062 | G32: 12.993 | H32: 17.446 | I32: 19.283 | J32: 72.329
A33: Total Noncurrent Assets | B33: BS_TOT_NON_CUR_ASSET | C33: 375.0105 | D33: 2696.529 | E33: 2687.247 | F33: 2711.271 | G33: 2644.545 | H33: 2995.923 | I33: 3005.595 | J33: 3125.137
A34: Total Assets | B34: BS_TOT_ASSET | C34: 376.0603 | D34: 2847.892 | E34: 2966.275 | F34: 3010.713 | G34: 3097.701 | H34: 3365.469 | I34: 3466.311 | J34: 3492.199
A36: Liabilities & Shareholders' Equity
A37: + Payables & Accruals | B37: ACCT_PAYABLE_ACCRUALS_DETAILED | C37: 0.2873 | D37: 55.739 | E37: 76.072 | F37: 87.825 | G37: 90.444 | H37: 115.132 | I37: 112.543 | J37: 154.283
A38: + Accounts Payable | B38: BS_ACCT_PAYABLE | C38: — | D38: 34.083 | E38: 49.992 | F38: 65.288 | G38: 68.566 | H38: 61.428 | I38: 68.104 | J38: 85.667
A39: + Accrued Taxes | B39: BS_TAXES_PAYABLE | C39: 0.0699 | D39: 0 | E39: 14.2 | F39: 4.4 | G39: 12.1 | H39: 11.8 | I39: 11.6 | J39: 12.6
A40: + Other Payables & Accruals | B40: BS_ACCRUAL | C40: 0.2174 | D40: 21.656 | E40: 11.88 | F40: 18.137 | G40: 9.778 | H40: 41.904 | I40: 32.839 | J40: 56.016
A41: + ST Debt | B41: BS_ST_BORROW | C41: 0 | D41: 11.496 | E41: 11.268 | F41: 11.268 | G41: 23.766 | H41: 27.622 | I41: 28.34 | J41: 7.834
A42: + ST Borrowings | B42: SHORT_TERM_DEBT_DETAILED | C42: 0 | D42: 0 | E42: 0 | F42: 0 | G42: 0 | H42: 0 | I42: 0 | J42: 0
A43: + ST Lease Liabilities | B43: ST_CAPITALIZED_LEASE_LIABILITIES | C43: 0 | D43: — | E43: — | F43: — | G43: 11.883 | H43: 13.811 | I43: 14.17 | J43: 3.917
...

Sheet Cash Flow 
A2: Hostess Brands Inc (TWNK US) - Standardized
A4: In Millions of USD except Per Share | C4: FY 2015 | D4: FY 2016 | E4: FY 2017 | F4: FY 2018 | G4: FY 2019 | H4: FY 2020 | I4: FY 2021 | J4: FY 2022 | K4: Last 12M
A5: 12 Months Ending | C5: 12/31/2015 | D5: 12/31/2016 | E5: 12/31/2017 | F5: 12/31/2018 | G5: 12/31/2019 | H5: 12/31/2020 | I5: 12/31/2021 | J5: 12/31/2022 | K5: 09/30/2023
A6: Cash from Operating Activities
A7: + Net Income | B7: CF_NET_INC | C7: -0.4699 | D7: 52.807 | E7: 223.897 | F7: 142.051 | G7: 4.299 | H7: 104.676 | I7: 119.299 | J7: 164.195 | K7: 126.479
A8: + Depreciation & Amortization | B8: CF_DEPR_AMORT | C8: 0 | D8: 16.108 | E8: 38.17 | F8: 41.411 | G8: 43.334 | H8: 54.94 | I8: 51.681 | J8: 60.086 | K8: 60.659
A9: + Non-Cash Items | B9: NON_CASH_ITEMS_DETAILED | C9: — | D9: 30.28 | E9: -38.104 | F9: -53.617 | G9: 97.051 | H9: -7.23 | I9: 34.643 | J9: 37.764 | K9: 21.395
A10: + Stock-Based Compensation | B10: CF_STOCK_BASED_COMPENSATION | C10: — | D10: 30.638 | E10: 7.413 | F10: 5.6 | G10: 9.231 | H10: 8.671 | I10: 9.585 | J10: 10.45 | K10: 6.995
A11: + Deferred Income Taxes | B11: CF_DEF_INC_TAX | C11: — | D11: -7.815 | E11: -81.27 | F11: 10.255 | G11: 14.121 | H11: 16.806 | I11: 18.995 | J11: 16.511 | K11: 26.234001
A12: + Other Non-Cash Adj | B12: OTHER_NON_CASH_ADJ_LESS_DETAILED | C12: — | D12: 7.457 | E12: 35.753 | F12: -69.472 | G12: 73.699 | H12: -32.707 | I12: 6.063 | J12: 10.803 | K12: 0.885
A13: + Chg in Non-Cash Work Cap | B13: CF_CHNG_NON_CASH_WORK_CAP | C13: 0.0282 | D13: 16.637 | E13: -60.278 | F13: 13.81 | G13: -0.71 | H13: 6.857 | I13: -2.594 | J13: -13.243 | K13: 3.093
A14: + (Inc) Dec in Accts Receiv | B14: CF_ACCT_RCV_UNBILLED_REV | C14: — | D14: -16.164 | E14: -11.775 | F14: -3.667 | G14: -2.57 | H14: 4.434 | I14: -22.728 | J14: -20.763 | K14: 11.751001
A15: + (Inc) Dec in Inventories | B15: CF_CHANGE_IN_INVENTORIES | C15: — | D15: 5.901 | E15: -3.901 | F15: 3.569 | G15: -12.477 | H15: 5.824 | I15: -3.465 | J15: -12.593 | K15: 3.393
A16: + Inc (Dec) in Accts Payable | B16: CF_CHANGE_IN_ACCOUNTS_PAYABLE | C16: — | D16: — | E16: 0 | F16: — | G16: — | H16: — | I16: — | J16: 0
A17: + Inc (Dec) in Other | B17: INC_DEC_IN_OT_OP_AST_LIAB_DETAIL | C17: 0.0282 | D17: 26.9 | E17: -44.602 | F17: 13.908 | G17: 14.337 | H17: -3.401 | I17: 23.599 | J17: 20.113 | K17: 1.624
A18: + Net Cash From Disc Ops | B18: CF_NET_CASH_DISCONT_OPS_OPER | C18: 0 | D18: 0 | E18: 0 | F18: 0 | G18: 0 | H18: 0 | I18: 0 | J18: 0 | K18: 0
A19: Cash from Operating Activities | B19: CF_CASH_FROM_OPER | C19: -0.4418 | D19: 115.832 | E19: 163.685 | F19: 143.655 | G19: 143.974 | H19: 159.243 | I19: 203.029 | J19: 248.802 | K19: 227.812
A21: Cash from Investing Activities
A22: + Change in Fixed & Intang | B22: FIXED_INTANG_ASST_CHANGE | C22: 0 | D22: -33.798 | E22: -35.209 | F22: -47.785 | G22: -40.484 | H22: -58.252 | I22: -65.425 | J22: -130.497 | K22: -62.152
A23: + Disp in Fixed & Intang | B23: DISPOSAL_OF_FIXED_INTANG | C23: 0 | D23: 4 | E23: 0.085 | F23: 0.639 | G23: 0 | H23: 0 | I23: 0 | J23: 0 | K23: 0
A24: + Disp of Fixed Prod Assets | B24: CF_DISPOSAL_OF_FIXED_PROD_ASSETS | C24: 0 | D24: 4 | E24: 0.085 | F24: 0.639 | G24: 0 | H24: — | I24: 0 | J24: 0
A25: + Disp of Intangible Assets | B25: CF_DISPOSAL_OF_INTANGIBLE_ASSETS | C25: 0 | D25: 0 | E25: 0 | F25: 0 | G25: 0 | H25: — | I25: 0 | J25: 0
A26: + Acq of Fixed & Intang | B26: ACQUIS_OF_FIXED_INTANG | C26: 0 | D26: -37.798 | E26: -35.294 | F26: -48.424 | G26: -40.484 | H26: -58.252 | I26: -65.425 | J26: -130.497 | K26: -62.152
A27: + Acq of Fixed Prod Assets | B27: CF_PURCHASE_OF_FIXED_PROD_ASSETS | C27: 0 | D27: -37.798 | E27: -32.913 | F27: -44.585 | G27: -34.875 | H27: -51.983 | I27: -60.803 | J27: -119.374 | K27: -56.677
A28: + Acq of Intangible Assets | B28: CF_ACQUISITION_OF_INTANG_ASSETS | C28: 0 | D28: 0 | E28: -2.381 | F28: -3.839 | G28: -5.609 | H28: -6.269 | I28: -4.622 | J28: -11.123 | K28: -5.475
A29: + Net Change in LT Investment | B29: NET_CHG_IN_LT_INVEST_DETAILED | C29: 0 | D29: 0 | E29: 0 | F29: 0 | G29: 0 | H29: 0 | I29: 0 | J29: 0 | K29: 0
A30: + Dec in LT Investment | B30: CF_DECR_INVEST | C30: 0 | D30: 0 | E30: 0 | F30: 0 | G30: 0 | H30: 0 | I30: 0 | J30: 0 | K30: 0
A31: + Inc in LT Investment | B31: CF_INCR_INVEST | C31: 0 | D31: 0 | E31: 0 | F31: 0 | G31: 0 | H31: 0 | I31: 0 | J31: 0 | K31: 0
A32: + Net Cash From Acq & Div | B32: CF_NT_CSH_RCVD_PD_FOR_ACQUIS_DIV | C32: 0 | D32: -470.977 | E32: 0 | F32: -23.16 | G32: 63.345 | H32: -316.013 | I32: 0 | J32: 0 | K32: 0
A33: + Cash from Divestitures | B33: CF_CASH_FOR_DIVESTITURES | C33: 0 | D33: 0 | E33: 0 | F33: 0 | G33: 63.345 | H33: 0 | I33: 0 | J33: 0 | K33: 0
A34: + Cash for Acq of Subs | B34: CF_CASH_FOR_ACQUIS_SUBSIDIARIES | C34: 0 | D34: -470.977 | E34: 0 | F34: -23.16 | G34: 0 | H34: -316.013 | I34: 0 | J34: 0 | K34: 0
A35: + Cash for JVs | B35: CF_CASH_FOR_JOINT_VENTURES_ASSOC | C35: 0 | D35: 0 | E35: 0 | F35: 0 | G35: 0 | H35: 0 | I35: 0 | J35: 0 | K35: 0
A36: + Other Investing Activities | B36: OTHER_INVESTING_ACT_DETAILED | C36: -375.0105 | D36: 0 | E36: 0 | F36: 0 | G36: 0 | H36: 0 | I36: 0 | J36: -17.424 | K36: -0.75
A37: + Net Cash From Disc Ops | B37: CF_NET_CASH_DISCONTINUED_OPS_INV | C37: 0 | D37: 0 | E37: 0 | F37: 0 | G37: 0 | H37: 0 | I37: 0 | J37: 0 | K37: 0
A38: Cash from Investing Activities | B38: CF_CASH_FROM_INV_ACT | C38: -375.0105 | D38: -504.775 | E38: -35.209 | F38: -70.945 | G38: 22.861 | H38: -374.265 | I38: -65.425 | J38: -147.921 | K38: -111.541
A40: Cash from Financing Activities
A41: + Dividends Paid | B41: CF_DVD_PAID | C41: 0 | D41: 0 | E41: 0 | F41: 0 | G41: 0 | H41: 0 | I41: 0 | J41: 0 | K41: 0
A42: + Cash From (Repayment) Debt | B42: PROC_FR_REPAYMNTS_BOR_DETAILED | C42: -8.2821 | D42: -226.207 | E42: -6.21 | F42: -10.105 | G42: -9.894 | H42: 125.72 | I42: -11.167 | J42: -108.375 | K42: -0.683
A43: + Cash From (Repay) ST Debt | B43: CF_NET_CHG_ST_DEBT_CPTL_LEAS | C43: -7.5 | D43: — | E43: — | F43: — | G43: 0 | H43: 0 | I43: 0 | J43: 0
A44: + Cash From LT Debt | B44: CF_LT_DEBT_CAP_LEAS_PROCEEDS | C44: 0 | D44: 0 | E44: 0 | F44: 0 | G44: 0 | H44: 136.888 | I44: 0 | J44: 0 | K44: 336.663
...

Sheet Equity Valuation- Peers data 
A1: Name | B1: Mkt Cap (M) | C1: EV (M) | D1: EV/EBITDA TTM | E1: EV/EBITDA FY1 | F1: EV/EBITDA FY2 | G1: P/E
A2: Hostess Brands Inc | B2: 4449.47 | C2: 5358.33 | D2: 18.69 | E2: 16.58 | F2: 15.57 | G2: 28.52
A3: Median | B3: 13927.99 | C3: 17226.89 | D3: 13.7 | E3: 10.14 | F3: 9.81 | G3: 20.5
A4: Mondelez International | B4: 97093.03 | C4: 118915.03 | D4: 15.32 | E4: 12.52 | F4: 10.94 | G4: 21.8
A5: Kraft Heinz Co/The | B5: 41307.54 | C5: 61239.54 | D5: 12.95 | E5: 9.32 | F5: 8.9 | G5: 9.49
A6: Hormel Foods Corp | B6: 20416.54 | C6: 22799.31 | D6: 14.24 | E6: 13.32 | F6: 12.97 | G6: 21.4
A7: Tyson Foods Inc | B7: 18688.25 | C7: 26582.25 | D7: 4.59 | E7: 7.15 | F7: 5.76 | G7: 5.95
A8: Lamb Weston Holdings Inc | B8: 14409.35 | C8: 17722.75 | D8: 15.61 | E8: 11.18 | F8: 10.64 | G8: 19.59
A9: J M Smucker Co/The | B9: 13446.62 | C9: 16731.02 | D9: 26.53 | E9: 8.77 | F9: 8.23 | G9: 17.35
A10: Post Holdings Inc | B10: 5336.42 | C10: 11070.32 | D10: 13.16 | E10: 8.73 | F10: 8.23 | G10: 53.95
A11: Flowers Foods Inc | B11: 4942.77 | C11: 5952.34 | D11: 11.73 | E11: 10.59 | F11: 10.5 | G11: 18.42
A12: Simply Good Foods Co/The | B12: 3287.11 | C12: 3526.02 | D12: 15.06 | E12: 12.18 | F12: 11.04 | G12: 24.52
A13: Hain Celestial Group Inc | B13: 888.48 | C13: 1764.45 | D13: 12.38 | E13: 9.69 | F13: 9.12 | G13: 33.55
